Workbook

Sheet Column Name
A1: Column Name | B1: Mapping to Existing DB Schema | C1: Data Type | D1: Data Example | E1: Indonesia | F1: Expat | G1: HR | H1: Finance | I1: All Admin | J1: IS New | K1: Table Name
A2: Insurance (Endorsment) | B2: insurance_endorsement | C2: =VLOOKUP([1]!Table2[[#This Row],[Column Name]],'[1]Database Schema Proposed V2'!$A:$H,8,FALSE) -> BIT | D2: 0 (0,1) | E2: Y | F2: Y | G2: Y | H2: Y | I2: Y | J2: =VLOOKUP([1]!Table2[[#This Row],[Mapping to Existing DB Schema]],'[1]Database Schema Proposed V2'!$K:$O,5,FALSE) -> NO | K2: =VLOOKUP([1]!Table2[[#This Row],[Mapping to Existing DB Schema]],'[1]Database Schema Proposed V2'!$Q:$R,2,FALSE) -> employee_insurance
A3: Insurance Card Owlexa | B3: insurance_owlexa | C3: =VLOOKUP([1]!Table2[[#This Row],[Column Name]],'[1]Database Schema Proposed V2'!$A:$H,8,FALSE) -> BIT | D3: 1 (0,1) | E3: Y | F3: Y | G3: Y | H3: Y | I3: Y | J3: =VLOOKUP([1]!Table2[[#This Row],[Mapping to Existing DB Schema]],'[1]Database Schema Proposed V2'!$K:$O,5,FALSE) -> NO | K3: =VLOOKUP([1]!Table2[[#This Row],[Mapping to Existing DB Schema]],'[1]Database Schema Proposed V2'!$Q:$R,2,FALSE) -> employee_insurance
A4: Insurance Card FPG | B4: insurance_fpg | C4: =VLOOKUP([1]!Table2[[#This Row],[Column Name]],'[1]Database Schema Proposed V2'!$A:$H,8,FALSE) -> BIT | D4: 0 (0,1) | E4: Y | F4: Y | G4: Y | H4: Y | I4: Y | J4: =VLOOKUP([1]!Table2[[#This Row],[Mapping to Existing DB Schema]],'[1]Database Schema Proposed V2'!$K:$O,5,FALSE) -> NO | K4: =VLOOKUP([1]!Table2[[#This Row],[Mapping to Existing DB Schema]],'[1]Database Schema Proposed V2'!$Q:$R,2,FALSE) -> employee_insurance
A5: Emp. ID | B5: employee_id | C5: =VLOOKUP([1]!Table2[[#This Row],[Column Name]],'[1]Database Schema Proposed V2'!$A:$H,8,FALSE) -> VARCHAR(20) | D5: MTI12345 (Free Text) | E5: Y | F5: Y | G5: Y | H5: Y | I5: Y | J5: =VLOOKUP([1]!Table2[[#This Row],[Mapping to Existing DB Schema]],'[1]Database Schema Proposed V2'!$K:$O,5,FALSE) -> NO | K5: =VLOOKUP([1]!Table2[[#This Row],[Mapping to Existing DB Schema]],'[1]Database Schema Proposed V2'!$Q:$R,2,FALSE) -> employee_bank, employee_contact, employee_core, employee_employment, employee_insurance, employee_onboard, employee_travel
A6: IMIP ID | B6: imip_id | C6: =VLOOKUP([1]!Table2[[#This Row],[Column Name]],'[1]Database Schema Proposed V2'!$A:$H,8,FALSE) -> VARCHAR(20) | D6: IMIP77889 (Free Text) | E6: Y | G6: Y | H6: =VLOOKUP('Column Name'!$B6,[2]Sheet2!$D:$F,3,FALSE) -> Y | I6: Y | J6: =VLOOKUP([1]!Table2[[#This Row],[Mapping to Existing DB Schema]],'[1]Database Schema Proposed V2'!$K:$O,5,FALSE) -> NO | K6: =VLOOKUP([1]!Table2[[#This Row],[Mapping to Existing DB Schema]],'[1]Database Schema Proposed V2'!$Q:$R,2,FALSE) -> employee_core
A7: Employee Name | B7: name | C7: =VLOOKUP([1]!Table2[[#This Row],[Column Name]],'[1]Database Schema Proposed V2'!$A:$H,8,FALSE) -> VARCHAR(100) | D7: Andi Saputra (Free Text) | E7: Y | F7: Y | G7: Y | H7: Y | I7: Y | J7: =VLOOKUP([1]!Table2[[#This Row],[Mapping to Existing DB Schema]],'[1]Database Schema Proposed V2'!$K:$O,5,FALSE) -> NO | K7: =VLOOKUP([1]!Table2[[#This Row],[Mapping to Existing DB Schema]],'[1]Database Schema Proposed V2'!$Q:$R,2,FALSE) -> employee_core
A8: Gender | B8: gender | C8: =VLOOKUP([1]!Table2[[#This Row],[Column Name]],'[1]Database Schema Proposed V2'!$A:$H,8,FALSE) -> VARCHAR(10) | D8: Male (Dropdown: Male,Female) | E8: Y | F8: Y | G8: Y | H8: Y | I8: Y | J8: =VLOOKUP([1]!Table2[[#This Row],[Mapping to Existing DB Schema]],'[1]Database Schema Proposed V2'!$K:$O,5,FALSE) -> NO | K8: =VLOOKUP([1]!Table2[[#This Row],[Mapping to Existing DB Schema]],'[1]Database Schema Proposed V2'!$Q:$R,2,FALSE) -> employee_core
A9: Place of Birth | B9: place_of_birth | C9: =VLOOKUP([1]!Table2[[#This Row],[Column Name]],'[1]Database Schema Proposed V2'!$A:$H,8,FALSE) -> VARCHAR(50) | D9: Jakarta (Free Text) | E9: Y | F9: Y | G9: Y | I9: Y | J9: =VLOOKUP([1]!Table2[[#This Row],[Mapping to Existing DB Schema]],'[1]Database Schema Proposed V2'!$K:$O,5,FALSE) -> NO | K9: =VLOOKUP([1]!Table2[[#This Row],[Mapping to Existing DB Schema]],'[1]Database Schema Proposed V2'!$Q:$R,2,FALSE) -> employee_core
A10: Date of Birth | B10: date_of_birth | C10: =VLOOKUP([1]!Table2[[#This Row],[Column Name]],'[1]Database Schema Proposed V2'!$A:$H,8,FALSE) -> DATE | D10: 32975 | E10: Y | F10: Y | G10: Y | I10: Y | J10: =VLOOKUP([1]!Table2[[#This Row],[Mapping to Existing DB Schema]],'[1]Database Schema Proposed V2'!$K:$O,5,FALSE) -> NO | K10: =VLOOKUP([1]!Table2[[#This Row],[Mapping to Existing DB Schema]],'[1]Database Schema Proposed V2'!$Q:$R,2,FALSE) -> employee_core
A11: Age | B11: age | C11: =VLOOKUP([1]!Table2[[#This Row],[Column Name]],'[1]Database Schema Proposed V2'!$A:$H,8,FALSE) -> INT | D11: 34 (Calculated) | E11: Y | F11: Y | G11: Y | I11: Y | J11: =VLOOKUP([1]!Table2[[#This Row],[Mapping to Existing DB Schema]],'[1]Database Schema Proposed V2'!$K:$O,5,FALSE) -> NO | K11: =VLOOKUP([1]!Table2[[#This Row],[Mapping to Existing DB Schema]],'[1]Database Schema Proposed V2'!$Q:$R,2,FALSE) -> employee_core
A12: Marital Status | B12: marital_status | C12: =VLOOKUP([1]!Table2[[#This Row],[Column Name]],'[1]Database Schema Proposed V2'!$A:$H,8,FALSE) -> VARCHAR(20) | D12: Married (Dropdown: Single,Married,Divorced,Widowed) | E12: Y | F12: Y | G12: Y | H12: Y | I12: Y | J12: =VLOOKUP([1]!Table2[[#This Row],[Mapping to Existing DB Schema]],'[1]Database Schema Proposed V2'!$K:$O,5,FALSE) -> NO | K12: =VLOOKUP([1]!Table2[[#This Row],[Mapping to Existing DB Schema]],'[1]Database Schema Proposed V2'!$Q:$R,2,FALSE) -> employee_core
A13: Tax Status | B13: tax_status | C13: =VLOOKUP([1]!Table2[[#This Row],[Column Name]],'[1]Database Schema Proposed V2'!$A:$H,8,FALSE) -> VARCHAR(10) | D13: TK0 (Dropdown: TK0,TK1,TK2,TK3,K0,K1,K2,K3) | E13: Y | F13: Y | G13: Y | I13: Y | J13: =VLOOKUP([1]!Table2[[#This Row],[Mapping to Existing DB Schema]],'[1]Database Schema Proposed V2'!$K:$O,5,FALSE) -> NO | K13: =VLOOKUP([1]!Table2[[#This Row],[Mapping to Existing DB Schema]],'[1]Database Schema Proposed V2'!$Q:$R,2,FALSE) -> employee_core
A14: Spouse Name | B14: spouse_name | C14: =VLOOKUP([1]!Table2[[#This Row],[Column Name]],'[1]Database Schema Proposed V2'!$A:$H,8,FALSE) -> VARCHAR(100) | D14: Siti Aminah (Free Text) | E14: Y | G14: Y | H14: Y | I14: Y | J14: =VLOOKUP([1]!Table2[[#This Row],[Mapping to Existing DB Schema]],'[1]Database Schema Proposed V2'!$K:$O,5,FALSE) -> NO | K14: =VLOOKUP([1]!Table2[[#This Row],[Mapping to Existing DB Schema]],'[1]Database Schema Proposed V2'!$Q:$R,2,FALSE) -> employee_contact
A15: Child Name 1 | B15: child_name_1 | C15: =VLOOKUP([1]!Table2[[#This Row],[Column Name]],'[1]Database Schema Proposed V2'!$A:$H,8,FALSE) -> VARCHAR(100) | D15: Budi (Free Text) | E15: Y | G15: Y | H15: Y | I15: Y | J15: =VLOOKUP([1]!Table2[[#This Row],[Mapping to Existing DB Schema]],'[1]Database Schema Proposed V2'!$K:$O,5,FALSE) -> NO | K15: =VLOOKUP([1]!Table2[[#This Row],[Mapping to Existing DB Schema]],'[1]Database Schema Proposed V2'!$Q:$R,2,FALSE) -> employee_contact
A16: Child Name 2 | B16: child_name_2 | C16: =VLOOKUP([1]!Table2[[#This Row],[Column Name]],'[1]Database Schema Proposed V2'!$A:$H,8,FALSE) -> VARCHAR(100) | D16: Sari (Free Text) | E16: Y | G16: Y | H16: Y | I16: Y | J16: =VLOOKUP([1]!Table2[[#This Row],[Mapping to Existing DB Schema]],'[1]Database Schema Proposed V2'!$K:$O,5,FALSE) -> NO | K16: =VLOOKUP([1]!Table2[[#This Row],[Mapping to Existing DB Schema]],'[1]Database Schema Proposed V2'!$Q:$R,2,FALSE) -> employee_contact
A17: Child Name 3 | B17: child_name_3 | C17: =VLOOKUP([1]!Table2[[#This Row],[Column Name]],'[1]Database Schema Proposed V2'!$A:$H,8,FALSE) -> VARCHAR(100) | D17: – (Free Text) | E17: Y | G17: Y | H17: Y | I17: Y | J17: =VLOOKUP([1]!Table2[[#This Row],[Mapping to Existing DB Schema]],'[1]Database Schema Proposed V2'!$K:$O,5,FALSE) -> NO | K17: =VLOOKUP([1]!Table2[[#This Row],[Mapping to Existing DB Schema]],'[1]Database Schema Proposed V2'!$Q:$R,2,FALSE) -> employee_contact
A18: Religion | B18: religion | C18: =VLOOKUP([1]!Table2[[#This Row],[Column Name]],'[1]Database Schema Proposed V2'!$A:$H,8,FALSE) -> VARCHAR(30) | D18: Islam (Dropdown: Islam,Kristen Protestan,Katolik,Hindu,Buddha,Konghucu,Lainnya) | E18: Y | F18: Y | G18: Y | I18: Y | J18: =VLOOKUP([1]!Table2[[#This Row],[Mapping to Existing DB Schema]],'[1]Database Schema Proposed V2'!$K:$O,5,FALSE) -> NO | K18: =VLOOKUP([1]!Table2[[#This Row],[Mapping to Existing DB Schema]],'[1]Database Schema Proposed V2'!$Q:$R,2,FALSE) -> employee_core
A19: Nationality | B19: nationality | C19: =VLOOKUP([1]!Table2[[#This Row],[Column Name]],'[1]Database Schema Proposed V2'!$A:$H,8,FALSE) -> VARCHAR(50) | D19: Indonesia (Dropdown: Indonesia,China,Philippines,India,Thailand,Malaysia,Vietnam,Other) | E19: Y | F19: Y | G19: Y | I19: Y | J19: =VLOOKUP([1]!Table2[[#This Row],[Mapping to Existing DB Schema]],'[1]Database Schema Proposed V2'!$K:$O,5,FALSE) -> NO | K19: =VLOOKUP([1]!Table2[[#This Row],[Mapping to Existing DB Schema]],'[1]Database Schema Proposed V2'!$Q:$R,2,FALSE) -> employee_core
A20: Blood Type | B20: blood_type | C20: =VLOOKUP([1]!Table2[[#This Row],[Column Name]],'[1]Database Schema Proposed V2'!$A:$H,8,FALSE) -> VARCHAR(5) | D20: O (Dropdown: A,B,AB,O,A+,B+,O+,AB+) | E20: Y | F20: Y | G20: Y | I20: Y | J20: =VLOOKUP([1]!Table2[[#This Row],[Mapping to Existing DB Schema]],'[1]Database Schema Proposed V2'!$K:$O,5,FALSE) -> NO | K20: =VLOOKUP([1]!Table2[[#This Row],[Mapping to Existing DB Schema]],'[1]Database Schema Proposed V2'!$Q:$R,2,FALSE) -> employee_core
A21: Mobile Phone | B21: phone_number | C21: =VLOOKUP([1]!Table2[[#This Row],[Column Name]],'[1]Database Schema Proposed V2'!$A:$H,8,FALSE) -> VARCHAR(20) | D21: 081234567890 (Free Text) | E21: Y | F21: Y | G21: Y | H21: Y | I21: Y | J21: =VLOOKUP([1]!Table2[[#This Row],[Mapping to Existing DB Schema]],'[1]Database Schema Proposed V2'!$K:$O,5,FALSE) -> NO | K21: =VLOOKUP([1]!Table2[[#This Row],[Mapping to Existing DB Schema]],'[1]Database Schema Proposed V2'!$Q:$R,2,FALSE) -> employee_contact
A22: Emergency Contact Name | B22: emergency_contact_name | C22: =VLOOKUP([1]!Table2[[#This Row],[Column Name]],'[1]Database Schema Proposed V2'!$A:$H,8,FALSE) -> VARCHAR(100) | D22: Rudi (Free Text) | E22: Y | G22: Y | I22: Y | J22: =VLOOKUP([1]!Table2[[#This Row],[Mapping to Existing DB Schema]],'[1]Database Schema Proposed V2'!$K:$O,5,FALSE) -> NO | K22: =VLOOKUP([1]!Table2[[#This Row],[Mapping to Existing DB Schema]],'[1]Database Schema Proposed V2'!$Q:$R,2,FALSE) -> employee_contact
A23: Emergency Contact Phone | B23: emergency_contact_phone | C23: =VLOOKUP([1]!Table2[[#This Row],[Column Name]],'[1]Database Schema Proposed V2'!$A:$H,8,FALSE) -> VARCHAR(20) | D23: 081298765432 (Free Text) | E23: Y | G23: Y | I23: Y | J23: =VLOOKUP([1]!Table2[[#This Row],[Mapping to Existing DB Schema]],'[1]Database Schema Proposed V2'!$K:$O,5,FALSE) -> NO | K23: =VLOOKUP([1]!Table2[[#This Row],[Mapping to Existing DB Schema]],'[1]Database Schema Proposed V2'!$Q:$R,2,FALSE) -> employee_contact
A24: Kartu Keluarga No | B24: kartu_keluarga_no | C24: =VLOOKUP([1]!Table2[[#This Row],[Column Name]],'[1]Database Schema Proposed V2'!$A:$H,8,FALSE) -> VARCHAR(25) | D24: 3275XXXXXXXX (Free Text) | E24: Y | G24: Y | H24: Y | I24: Y | J24: =VLOOKUP([1]!Table2[[#This Row],[Mapping to Existing DB Schema]],'[1]Database Schema Proposed V2'!$K:$O,5,FALSE) -> NO | K24: =VLOOKUP([1]!Table2[[#This Row],[Mapping to Existing DB Schema]],'[1]Database Schema Proposed V2'!$Q:$R,2,FALSE) -> employee_core
A25: KTP No | B25: ktp_no | C25: =VLOOKUP([1]!Table2[[#This Row],[Column Name]],'[1]Database Schema Proposed V2'!$A:$H,8,FALSE) -> VARCHAR(20) | D25: 3174XXXXXXXX (Free Text) | E25: Y | F25: Y | G25: Y | I25: Y | J25: =VLOOKUP([1]!Table2[[#This Row],[Mapping to Existing DB Schema]],'[1]Database Schema Proposed V2'!$K:$O,5,FALSE) -> NO | K25: =VLOOKUP([1]!Table2[[#This Row],[Mapping to Existing DB Schema]],'[1]Database Schema Proposed V2'!$Q:$R,2,FALSE) -> employee_core
A26: KTP Address | B26: address | C26: =VLOOKUP([1]!Table2[[#This Row],[Column Name]],'[1]Database Schema Proposed V2'!$A:$H,8,FALSE) -> VARCHAR(255) | D26: Jl. Mawar No. 12 (Free Text) | E26: Y | F26: Y | G26: Y | H26: =VLOOKUP('Column Name'!$B26,[2]Sheet2!$D:$F,3,FALSE) -> Y | I26: Y | J26: =VLOOKUP([1]!Table2[[#This Row],[Mapping to Existing DB Schema]],'[1]Database Schema Proposed V2'!$K:$O,5,FALSE) -> NO | K26: =VLOOKUP([1]!Table2[[#This Row],[Mapping to Existing DB Schema]],'[1]Database Schema Proposed V2'!$Q:$R,2,FALSE) -> employee_contact
A27: KTP City | B27: city | C27: =VLOOKUP([1]!Table2[[#This Row],[Column Name]],'[1]Database Schema Proposed V2'!$A:$H,8,FALSE) -> VARCHAR(100) | D27: Jakarta Barat (Free Text) | E27: Y | F27: Y | G27: Y | I27: Y | J27: =VLOOKUP([1]!Table2[[#This Row],[Mapping to Existing DB Schema]],'[1]Database Schema Proposed V2'!$K:$O,5,FALSE) -> NO | K27: =VLOOKUP([1]!Table2[[#This Row],[Mapping to Existing DB Schema]],'[1]Database Schema Proposed V2'!$Q:$R,2,FALSE) -> employee_contact
A28: Poin of Hire | B28: point_of_hire | C28: =VLOOKUP([1]!Table2[[#This Row],[Column Name]],'[1]Database Schema Proposed V2'!$A:$H,8,FALSE) -> VARCHAR(100) | D28: Jakarta (Free Text) | E28: Y | F28: Y | G28: Y | H28: Y | I28: Y | J28: =VLOOKUP([1]!Table2[[#This Row],[Mapping to Existing DB Schema]],'[1]Database Schema Proposed V2'!$K:$O,5,FALSE) -> NO | K28: =VLOOKUP([1]!Table2[[#This Row],[Mapping to Existing DB Schema]],'[1]Database Schema Proposed V2'!$Q:$R,2,FALSE) -> employee_onboard
A29: Poin of Origin | B29: point_of_origin | C29: =VLOOKUP([1]!Table2[[#This Row],[Column Name]],'[1]Database Schema Proposed V2'!$A:$H,8,FALSE) -> VARCHAR(100) | D29: Surabaya (Free Text) | E29: Y | F29: Y | G29: Y | I29: Y | J29: =VLOOKUP([1]!Table2[[#This Row],[Mapping to Existing DB Schema]],'[1]Database Schema Proposed V2'!$K:$O,5,FALSE) -> NO | K29: =VLOOKUP([1]!Table2[[#This Row],[Mapping to Existing DB Schema]],'[1]Database Schema Proposed V2'!$Q:$R,2,FALSE) -> employee_onboard
A30: Education | B30: education | C30: =VLOOKUP([1]!Table2[[#This Row],[Column Name]],'[1]Database Schema Proposed V2'!$A:$H,8,FALSE) -> VARCHAR(50) | D30: S1 (Dropdown: SMP,SMA/SMK,D3,S1,S2,S3) | E30: Y | F30: Y | G30: Y | I30: Y | J30: =VLOOKUP([1]!Table2[[#This Row],[Mapping to Existing DB Schema]],'[1]Database Schema Proposed V2'!$K:$O,5,FALSE) -> NO | K30: =VLOOKUP([1]!Table2[[#This Row],[Mapping to Existing DB Schema]],'[1]Database Schema Proposed V2'!$Q:$R,2,FALSE) -> employee_core
A31: Schedule Type | B31: schedule_type | C31: =VLOOKUP([1]!Table2[[#This Row],[Column Name]],'[1]Database Schema Proposed V2'!$A:$H,8,FALSE) -> VARCHAR(50) | D31: Shift (Dropdown: Shift,Non-Shift,Office Hours,Roster 6:2,Roster 8:2) | E31: Y | F31: Y | G31: Y | I31: Y | J31: =VLOOKUP([1]!Table2[[#This Row],[Mapping to Existing DB Schema]],'[1]Database Schema Proposed V2'!$K:$O,5,FALSE) -> NO | K31: =VLOOKUP([1]!Table2[[#This Row],[Mapping to Existing DB Schema]],'[1]Database Schema Proposed V2'!$Q:$R,2,FALSE) -> employee_onboard
A32: First Join Date (Merdeka Group) | B32: first_join_date_merdeka | C32: =VLOOKUP([1]!Table2[[#This Row],[Column Name]],'[1]Database Schema Proposed V2'!$A:$H,8,FALSE) -> DATE | D32: 43845 | E32: Y | G32: Y | I32: Y | J32: =VLOOKUP([1]!Table2[[#This Row],[Mapping to Existing DB Schema]],'[1]Database Schema Proposed V2'!$K:$O,5,FALSE) -> NO | K32: =VLOOKUP([1]!Table2[[#This Row],[Mapping to Existing DB Schema]],'[1]Database Schema Proposed V2'!$Q:$R,2,FALSE) -> employee_onboard
A33: Transfer Merdeka Group | B33: transfer_merdeka | C33: =VLOOKUP([1]!Table2[[#This Row],[Column Name]],'[1]Database Schema Proposed V2'!$A:$H,8,FALSE) -> DATE | D33: 44621 | E33: Y | G33: Y | I33: Y | J33: =VLOOKUP([1]!Table2[[#This Row],[Mapping to Existing DB Schema]],'[1]Database Schema Proposed V2'!$K:$O,5,FALSE) -> NO | K33: =VLOOKUP([1]!Table2[[#This Row],[Mapping to Existing DB Schema]],'[1]Database Schema Proposed V2'!$Q:$R,2,FALSE) -> employee_onboard
A34: First Join Date | B34: first_join_date | C34: =VLOOKUP([1]!Table2[[#This Row],[Column Name]],'[1]Database Schema Proposed V2'!$A:$H,8,FALSE) -> DATE | D34: 43845 | E34: Y | F34: Y | G34: Y | H34: Y | I34: Y | J34: =VLOOKUP([1]!Table2[[#This Row],[Mapping to Existing DB Schema]],'[1]Database Schema Proposed V2'!$K:$O,5,FALSE) -> NO | K34: =VLOOKUP([1]!Table2[[#This Row],[Mapping to Existing DB Schema]],'[1]Database Schema Proposed V2'!$Q:$R,2,FALSE) -> employee_onboard
A35: Join Date | B35: join_date | C35: =VLOOKUP([1]!Table2[[#This Row],[Column Name]],'[1]Database Schema Proposed V2'!$A:$H,8,FALSE) -> DATE | D35: 43862 | E35: Y | F35: Y | G35: Y | I35: Y | J35: =VLOOKUP([1]!Table2[[#This Row],[Mapping to Existing DB Schema]],'[1]Database Schema Proposed V2'!$K:$O,5,FALSE) -> NO | K35: =VLOOKUP([1]!Table2[[#This Row],[Mapping to Existing DB Schema]],'[1]Database Schema Proposed V2'!$Q:$R,2,FALSE) -> employee_onboard
A36: Employment Status | B36: employment_status | C36: =VLOOKUP([1]!Table2[[#This Row],[Column Name]],'[1]Database Schema Proposed V2'!$A:$H,8,FALSE) -> VARCHAR(30) | D36: Permanent (Dropdown: Permanent,Contract,Probation,Internship) | E36: Y | F36: Y | G36: Y | H36: Y | I36: Y | J36: =VLOOKUP([1]!Table2[[#This Row],[Mapping to Existing DB Schema]],'[1]Database Schema Proposed V2'!$K:$O,5,FALSE) -> #N/A | K36: =VLOOKUP([1]!Table2[[#This Row],[Mapping to Existing DB Schema]],'[1]Database Schema Proposed V2'!$Q:$R,2,FALSE) -> employee_employment
A37: End Contract | B37: end_contract | C37: =VLOOKUP([1]!Table2[[#This Row],[Column Name]],'[1]Database Schema Proposed V2'!$A:$H,8,FALSE) -> DATE | D37: – | E37: Y | F37: Y | G37: Y | I37: Y | J37: =VLOOKUP([1]!Table2[[#This Row],[Mapping to Existing DB Schema]],'[1]Database Schema Proposed V2'!$K:$O,5,FALSE) -> NO | K37: =VLOOKUP([1]!Table2[[#This Row],[Mapping to Existing DB Schema]],'[1]Database Schema Proposed V2'!$Q:$R,2,FALSE) -> employee_onboard
A38: Years in Service | B38: years_in_service | C38: =VLOOKUP([1]!Table2[[#This Row],[Column Name]],'[1]Database Schema Proposed V2'!$A:$H,8,FALSE) -> VARCHAR(50) | D38: 4 Tahun 2 Bulan (Calculated) | E38: Y | F38: Y | G38: Y | I38: Y | J38: =VLOOKUP([1]!Table2[[#This Row],[Mapping to Existing DB Schema]],'[1]Database Schema Proposed V2'!$K:$O,5,FALSE) -> NO | K38: =VLOOKUP([1]!Table2[[#This Row],[Mapping to Existing DB Schema]],'[1]Database Schema Proposed V2'!$Q:$R,2,FALSE) -> employee_onboard
A39: Branch ID | B39: branch_id | C39: =VLOOKUP([1]!Table2[[#This Row],[Column Name]],'[1]Database Schema Proposed V2'!$A:$H,8,FALSE) -> VARCHAR(20) | D39: MTI-SITE-01 (Free Text) | E39: Y | J39: YES | K39: =VLOOKUP([1]!Table2[[#This Row],[Mapping to Existing DB Schema]],'[1]Database Schema Proposed V2'!$Q:$R,2,FALSE) -> employee_core
A40: Branch | B40: branch | C40: =VLOOKUP([1]!Table2[[#This Row],[Column Name]],'[1]Database Schema Proposed V2'!$A:$H,8,FALSE) -> VARCHAR(50) | D40: Morowali (Dropdown: Morowali,Jakarta,Surabaya) | E40: Y | J40: YES | K40: =VLOOKUP([1]!Table2[[#This Row],[Mapping to Existing DB Schema]],'[1]Database Schema Proposed V2'!$Q:$R,2,FALSE) -> employee_core
...

Sheet DB Schema
A1: Column Name | B1: IND Active | C1: IND Inactive | D1: EXP Active | E1: EXP Inactive | F1: Category | G1: Status | H1: Data Type | I1: Notes | J1: Need Column? | K1: Mapping to Existing DB Schema | L1: Existing Table Name | M1: Current Data Type | N1: IS Valid | O1: IS New | P1: Column Name | Q1: Mapping to Existing DB Schema | R1: Existing Table Name | S1: HR | T1: Finance | U1: All Admin | V1: Example Values
A2: Insurance (Endorsment) | B2: ✔ | C2: ✔ | D2: ✔ | E2: ✔ | F2: BOTH | G2: both | H2: BIT | I2: Checklist (V/✔) | J2: YES | K2: =VLOOKUP(A2,[1]Sheet4!A:B,2,FALSE) -> insurance_endorsement | L2: =VLOOKUP(K2,[3]Combined_Columns!$A:$B,2,FALSE) -> employee_insurance | M2: =VLOOKUP(K2,[3]Combined_Columns!$A:$E,5,FALSE) -> varchar | N2: =ISERROR(SEARCH(M2, H2)) -> TRUE | O2: NO | P2: Insurance (Endorsment) | Q2: insurance_endorsement | R2: employee_insurance | S2: =VLOOKUP(Q2,[2]Sheet2!$D:$E,2,FALSE) -> Confidential | T2: =VLOOKUP(Q2,[2]Sheet2!$D:$F,3,FALSE) -> Confidential | U2: =VLOOKUP(Q2,[2]Sheet2!$D:$G,4,FALSE) -> Confidential
A3: Insurance Card Owlexa | B3: ✔ | C3: ✔ | D3: ✔ | E3: ✔ | F3: BOTH | G3: both | H3: BIT | I3: Checklist | J3: YES | K3: =VLOOKUP(A3,[1]Sheet4!A:B,2,FALSE) -> insurance_owlexa | L3: =VLOOKUP(K3,[3]Combined_Columns!$A:$B,2,FALSE) -> employee_insurance | M3: =VLOOKUP(K3,[3]Combined_Columns!$A:$E,5,FALSE) -> varchar | N3: =ISERROR(SEARCH(M3, H3)) -> TRUE | O3: NO | P3: Insurance Card Owlexa | Q3: insurance_owlexa | R3: employee_insurance | S3: =VLOOKUP(Q3,[2]Sheet2!$D:$E,2,FALSE) -> Confidential | T3: =VLOOKUP(Q3,[2]Sheet2!$D:$F,3,FALSE) -> Confidential | U3: =VLOOKUP(Q3,[2]Sheet2!$D:$G,4,FALSE) -> Confidential
A4: Insurance Card FPG | B4: ✔ | C4: ✔ | D4: ✔ | E4: ✔ | F4: BOTH | G4: both | H4: BIT | I4: Checklist | J4: YES | K4: =VLOOKUP(A4,[1]Sheet4!A:B,2,FALSE) -> insurance_fpg | L4: =VLOOKUP(K4,[3]Combined_Columns!$A:$B,2,FALSE) -> employee_insurance | M4: =VLOOKUP(K4,[3]Combined_Columns!$A:$E,5,FALSE) -> varchar | N4: =ISERROR(SEARCH(M4, H4)) -> TRUE | O4: NO | P4: Insurance Card FPG | Q4: insurance_fpg | R4: employee_insurance | S4: =VLOOKUP(Q4,[2]Sheet2!$D:$E,2,FALSE) -> Confidential | T4: =VLOOKUP(Q4,[2]Sheet2!$D:$F,3,FALSE) -> Confidential | U4: =VLOOKUP(Q4,[2]Sheet2!$D:$G,4,FALSE) -> Confidential
A5: Emp. ID | B5: ✔ | C5: ✔ | D5: ✔ | E5: ✔ | F5: BOTH | G5: both | H5: VARCHAR(20) | I5: Primary Employee ID | J5: YES | K5: =VLOOKUP(A5,[1]Sheet4!A:B,2,FALSE) -> employee_id | L5: =VLOOKUP(K5,[3]Combined_Columns!$A:$B,2,FALSE) -> employee_bank, employee_contact, employee_core, employee_employment, employee_insurance, employee_onboard, employee_travel | M5: =VLOOKUP(K5,[3]Combined_Columns!$A:$E,5,FALSE) -> varchar | N5: =ISERROR(SEARCH(M5, H5)) -> FALSE | O5: NO | P5: Emp. ID | Q5: employee_id | R5: employee_bank, employee_contact, employee_core, employee_employment, employee_insurance, employee_onboard, employee_travel | S5: =VLOOKUP(Q5,[2]Sheet2!$D:$E,2,FALSE) -> Public | T5: =VLOOKUP(Q5,[2]Sheet2!$D:$F,3,FALSE) -> Public | U5: =VLOOKUP(Q5,[2]Sheet2!$D:$G,4,FALSE) -> Public
A6: IMIP ID | B6: ✔ | C6: ✔ | D6: — | E6: — | F6: IND | G6: both | H6: VARCHAR(20) | I6: IND only | J6: YES | K6: =VLOOKUP(A6,[1]Sheet4!A:B,2,FALSE) -> imip_id | L6: =VLOOKUP(K6,[3]Combined_Columns!$A:$B,2,FALSE) -> employee_core | M6: =VLOOKUP(K6,[3]Combined_Columns!$A:$E,5,FALSE) -> varchar | N6: =ISERROR(SEARCH(M6, H6)) -> FALSE | O6: NO | P6: IMIP ID | Q6: imip_id | R6: employee_core | S6: =VLOOKUP(Q6,[2]Sheet2!$D:$E,2,FALSE) -> Y | T6: =VLOOKUP(Q6,[2]Sheet2!$D:$F,3,FALSE) -> Y | U6: =VLOOKUP(Q6,[2]Sheet2!$D:$G,4,FALSE) -> 0
A7: Employee Name | B7: ✔ | C7: ✔ | D7: ✔ | E7: ✔ | F7: BOTH | G7: both | H7: VARCHAR(100) | I7: — | J7: YES | K7: =VLOOKUP(A7,[1]Sheet4!A:B,2,FALSE) -> name | L7: =VLOOKUP(K7,[3]Combined_Columns!$A:$B,2,FALSE) -> employee_core | M7: =VLOOKUP(K7,[3]Combined_Columns!$A:$E,5,FALSE) -> varchar | N7: =ISERROR(SEARCH(M7, H7)) -> FALSE | O7: NO | P7: Employee Name | Q7: name | R7: employee_core | S7: =VLOOKUP(Q7,[2]Sheet2!$D:$E,2,FALSE) -> Public | T7: =VLOOKUP(Q7,[2]Sheet2!$D:$F,3,FALSE) -> Public | U7: =VLOOKUP(Q7,[2]Sheet2!$D:$G,4,FALSE) -> Public
A8: Gender | B8: ✔ | C8: ✔ | D8: ✔ | E8: ✔ | F8: BOTH | G8: both | H8: VARCHAR(10) | I8: Male/Female | J8: YES | K8: =VLOOKUP(A8,[1]Sheet4!A:B,2,FALSE) -> gender | L8: =VLOOKUP(K8,[3]Combined_Columns!$A:$B,2,FALSE) -> employee_core | M8: =VLOOKUP(K8,[3]Combined_Columns!$A:$E,5,FALSE) -> char | N8: =ISERROR(SEARCH(M8, H8)) -> FALSE | O8: NO | P8: Gender | Q8: gender | R8: employee_core | S8: =VLOOKUP(Q8,[2]Sheet2!$D:$E,2,FALSE) -> Public | T8: =VLOOKUP(Q8,[2]Sheet2!$D:$F,3,FALSE) -> Public | U8: =VLOOKUP(Q8,[2]Sheet2!$D:$G,4,FALSE) -> Public
A9: Place of Birth | B9: ✔ | C9: ✔ | D9: ✔ | E9: ✔ | F9: BOTH | G9: both | H9: VARCHAR(50) | I9: — | J9: YES | K9: =VLOOKUP(A9,[1]Sheet4!A:B,2,FALSE) -> place_of_birth | L9: =VLOOKUP(K9,[3]Combined_Columns!$A:$B,2,FALSE) -> employee_core | M9: =VLOOKUP(K9,[3]Combined_Columns!$A:$E,5,FALSE) -> varchar | N9: =ISERROR(SEARCH(M9, H9)) -> FALSE | O9: NO | P9: Place of Birth | Q9: place_of_birth | R9: employee_core | S9: =VLOOKUP(Q9,[2]Sheet2!$D:$E,2,FALSE) -> Y | T9: =VLOOKUP(Q9,[2]Sheet2!$D:$F,3,FALSE) -> 0 | U9: =VLOOKUP(Q9,[2]Sheet2!$D:$G,4,FALSE) -> 0
A10: Date of Birth | B10: ✔ | C10: ✔ | D10: ✔ | E10: ✔ | F10: BOTH | G10: both | H10: DATE | I10: — | J10: YES | K10: =VLOOKUP(A10,[1]Sheet4!A:B,2,FALSE) -> date_of_birth | L10: =VLOOKUP(K10,[3]Combined_Columns!$A:$B,2,FALSE) -> employee_core | M10: =VLOOKUP(K10,[3]Combined_Columns!$A:$E,5,FALSE) -> date | N10: =ISERROR(SEARCH(M10, H10)) -> FALSE | O10: NO | P10: Date of Birth | Q10: date_of_birth | R10: employee_core | S10: =VLOOKUP(Q10,[2]Sheet2!$D:$E,2,FALSE) -> Y | T10: =VLOOKUP(Q10,[2]Sheet2!$D:$F,3,FALSE) -> 0 | U10: =VLOOKUP(Q10,[2]Sheet2!$D:$G,4,FALSE) -> 0
A11: Age | B11: ✔ | C11: ✔ | D11: ✔ | E11: ✔ | F11: BOTH | G11: both | H11: INT | I11: Calculated | J11: NO | K11: age | L11: =VLOOKUP(K11,[3]Combined_Columns!$A:$B,2,FALSE) -> employee_core | M11: =VLOOKUP(K11,[3]Combined_Columns!$A:$E,5,FALSE) -> int | N11: =ISERROR(SEARCH(M11, H11)) -> FALSE | O11: NO | P11: Age | Q11: age | R11: employee_core | S11: =VLOOKUP(Q11,[2]Sheet2!$D:$E,2,FALSE) -> Y | T11: =VLOOKUP(Q11,[2]Sheet2!$D:$F,3,FALSE) -> 0 | U11: =VLOOKUP(Q11,[2]Sheet2!$D:$G,4,FALSE) -> 0
A12: Marital Status | B12: ✔ | C12: ✔ | D12: ✔ | E12: ✔ | F12: BOTH | G12: both | H12: VARCHAR(20) | I12: Single/Married | J12: YES | K12: =VLOOKUP(A12,[1]Sheet4!A:B,2,FALSE) -> marital_status | L12: =VLOOKUP(K12,[3]Combined_Columns!$A:$B,2,FALSE) -> employee_core | M12: =VLOOKUP(K12,[3]Combined_Columns!$A:$E,5,FALSE) -> varchar | N12: =ISERROR(SEARCH(M12, H12)) -> FALSE | O12: NO | P12: Marital Status | Q12: marital_status | R12: employee_core | S12: =VLOOKUP(Q12,[2]Sheet2!$D:$E,2,FALSE) -> Confidential | T12: =VLOOKUP(Q12,[2]Sheet2!$D:$F,3,FALSE) -> Confidential | U12: =VLOOKUP(Q12,[2]Sheet2!$D:$G,4,FALSE) -> Confidential
A13: Tax Status | B13: ✔ | C13: ✔ | D13: ✔ | E13: ✔ | F13: BOTH | G13: both | H13: VARCHAR(10) | I13: K0/K1/K2 | J13: YES | K13: =VLOOKUP(A13,[1]Sheet4!A:B,2,FALSE) -> tax_status | L13: =VLOOKUP(K13,[3]Combined_Columns!$A:$B,2,FALSE) -> employee_core | M13: =VLOOKUP(K13,[3]Combined_Columns!$A:$E,5,FALSE) -> varchar | N13: =ISERROR(SEARCH(M13, H13)) -> FALSE | O13: NO | P13: Tax Status | Q13: tax_status | R13: employee_core | S13: =VLOOKUP(Q13,[2]Sheet2!$D:$E,2,FALSE) -> 0 | T13: =VLOOKUP(Q13,[2]Sheet2!$D:$F,3,FALSE) -> 0 | U13: =VLOOKUP(Q13,[2]Sheet2!$D:$G,4,FALSE) -> Y
A14: Spouse Name | B14: ✔ | C14: ✔ | D14: — | E14: — | F14: IND | G14: both | H14: VARCHAR(100) | I14: IND only | J14: YES | K14: =VLOOKUP(A14,[1]Sheet4!A:B,2,FALSE) -> spouse_name | L14: =VLOOKUP(K14,[3]Combined_Columns!$A:$B,2,FALSE) -> employee_contact | M14: =VLOOKUP(K14,[3]Combined_Columns!$A:$E,5,FALSE) -> varchar | N14: =ISERROR(SEARCH(M14, H14)) -> FALSE | O14: NO | P14: Spouse Name | Q14: spouse_name | R14: employee_contact | S14: =VLOOKUP(Q14,[2]Sheet2!$D:$E,2,FALSE) -> Confidential | T14: =VLOOKUP(Q14,[2]Sheet2!$D:$F,3,FALSE) -> Confidential | U14: =VLOOKUP(Q14,[2]Sheet2!$D:$G,4,FALSE) -> Confidential
A15: Child Name 1 | B15: ✔ | C15: ✔ | D15: — | E15: — | F15: IND | G15: both | H15: VARCHAR(100) | I15: IND only | J15: YES | K15: =VLOOKUP(A15,[1]Sheet4!A:B,2,FALSE) -> child_name_1 | L15: =VLOOKUP(K15,[3]Combined_Columns!$A:$B,2,FALSE) -> employee_contact | M15: =VLOOKUP(K15,[3]Combined_Columns!$A:$E,5,FALSE) -> varchar | N15: =ISERROR(SEARCH(M15, H15)) -> FALSE | O15: NO | P15: Child Name 1 | Q15: child_name_1 | R15: employee_contact | S15: =VLOOKUP(Q15,[2]Sheet2!$D:$E,2,FALSE) -> Confidential | T15: =VLOOKUP(Q15,[2]Sheet2!$D:$F,3,FALSE) -> Confidential | U15: =VLOOKUP(Q15,[2]Sheet2!$D:$G,4,FALSE) -> Confidential
A16: Child Name 2 | B16: ✔ | C16: ✔ | D16: — | E16: — | F16: IND | G16: both | H16: VARCHAR(100) | I16: IND only | J16: YES | K16: =VLOOKUP(A16,[1]Sheet4!A:B,2,FALSE) -> child_name_2 | L16: =VLOOKUP(K16,[3]Combined_Columns!$A:$B,2,FALSE) -> employee_contact | M16: =VLOOKUP(K16,[3]Combined_Columns!$A:$E,5,FALSE) -> varchar | N16: =ISERROR(SEARCH(M16, H16)) -> FALSE | O16: NO | P16: Child Name 2 | Q16: child_name_2 | R16: employee_contact | S16: =VLOOKUP(Q16,[2]Sheet2!$D:$E,2,FALSE) -> Confidential | T16: =VLOOKUP(Q16,[2]Sheet2!$D:$F,3,FALSE) -> Confidential | U16: =VLOOKUP(Q16,[2]Sheet2!$D:$G,4,FALSE) -> Confidential
A17: Child Name 3 | B17: ✔ | C17: ✔ | D17: — | E17: — | F17: IND | G17: both | H17: VARCHAR(100) | I17: IND only | J17: YES | K17: =VLOOKUP(A17,[1]Sheet4!A:B,2,FALSE) -> child_name_3 | L17: =VLOOKUP(K17,[3]Combined_Columns!$A:$B,2,FALSE) -> employee_contact | M17: =VLOOKUP(K17,[3]Combined_Columns!$A:$E,5,FALSE) -> varchar | N17: =ISERROR(SEARCH(M17, H17)) -> FALSE | O17: NO | P17: Child Name 3 | Q17: child_name_3 | R17: employee_contact | S17: =VLOOKUP(Q17,[2]Sheet2!$D:$E,2,FALSE) -> Confidential | T17: =VLOOKUP(Q17,[2]Sheet2!$D:$F,3,FALSE) -> Confidential | U17: =VLOOKUP(Q17,[2]Sheet2!$D:$G,4,FALSE) -> Confidential
A18: Religion | B18: ✔ | C18: ✔ | D18: ✔ | E18: ✔ | F18: BOTH | G18: both | H18: VARCHAR(30) | I18: — | J18: YES | K18: =VLOOKUP(A18,[1]Sheet4!A:B,2,FALSE) -> religion | L18: =VLOOKUP(K18,[3]Combined_Columns!$A:$B,2,FALSE) -> employee_core | M18: =VLOOKUP(K18,[3]Combined_Columns!$A:$E,5,FALSE) -> varchar | N18: =ISERROR(SEARCH(M18, H18)) -> FALSE | O18: NO | P18: Religion | Q18: religion | R18: employee_core | S18: =VLOOKUP(Q18,[2]Sheet2!$D:$E,2,FALSE) -> Y | T18: =VLOOKUP(Q18,[2]Sheet2!$D:$F,3,FALSE) -> 0 | U18: =VLOOKUP(Q18,[2]Sheet2!$D:$G,4,FALSE) -> Y
A19: Nationality | B19: ✔ | C19: ✔ | D19: ✔ | E19: ✔ | F19: BOTH | G19: both | H19: VARCHAR(50) | I19: e.g. Indonesia/China | J19: YES | K19: =VLOOKUP(A19,[1]Sheet4!A:B,2,FALSE) -> nationality | L19: =VLOOKUP(K19,[3]Combined_Columns!$A:$B,2,FALSE) -> employee_core | M19: =VLOOKUP(K19,[3]Combined_Columns!$A:$E,5,FALSE) -> varchar | N19: =ISERROR(SEARCH(M19, H19)) -> FALSE | O19: NO | P19: Nationality | Q19: nationality | R19: employee_core | S19: =VLOOKUP(Q19,[2]Sheet2!$D:$E,2,FALSE) -> Y | T19: =VLOOKUP(Q19,[2]Sheet2!$D:$F,3,FALSE) -> 0 | U19: =VLOOKUP(Q19,[2]Sheet2!$D:$G,4,FALSE) -> Y
A20: Blood Type | B20: ✔ | C20: ✔ | D20: ✔ | E20: ✔ | F20: BOTH | G20: both | H20: VARCHAR(5) | I20: A/B/AB/O | J20: YES | K20: =VLOOKUP(A20,[1]Sheet4!A:B,2,FALSE) -> blood_type | L20: =VLOOKUP(K20,[3]Combined_Columns!$A:$B,2,FALSE) -> employee_core | M20: =VLOOKUP(K20,[3]Combined_Columns!$A:$E,5,FALSE) -> varchar | N20: =ISERROR(SEARCH(M20, H20)) -> FALSE | O20: NO | P20: Blood Type | Q20: blood_type | R20: employee_core | S20: =VLOOKUP(Q20,[2]Sheet2!$D:$E,2,FALSE) -> Y | T20: =VLOOKUP(Q20,[2]Sheet2!$D:$F,3,FALSE) -> 0 | U20: =VLOOKUP(Q20,[2]Sheet2!$D:$G,4,FALSE) -> Y
A21: Mobile Phone | B21: ✔ | C21: ✔ | D21: ✔ | E21: ✔ | F21: BOTH | G21: both | H21: VARCHAR(20) | I21: — | J21: YES | K21: =VLOOKUP(A21,[1]Sheet4!A:B,2,FALSE) -> phone_number | L21: =VLOOKUP(K21,[3]Combined_Columns!$A:$B,2,FALSE) -> employee_contact | M21: =VLOOKUP(K21,[3]Combined_Columns!$A:$E,5,FALSE) -> varchar | N21: =ISERROR(SEARCH(M21, H21)) -> FALSE | O21: NO | P21: Mobile Phone | Q21: phone_number | R21: employee_contact | S21: =VLOOKUP(Q21,[2]Sheet2!$D:$E,2,FALSE) -> Public | T21: =VLOOKUP(Q21,[2]Sheet2!$D:$F,3,FALSE) -> Public | U21: =VLOOKUP(Q21,[2]Sheet2!$D:$G,4,FALSE) -> Public
A22: Emergency Contact Name | B22: ✔ | C22: ✔ | D22: — | E22: — | F22: IND | G22: both | H22: VARCHAR(100) | I22: IND only | J22: YES | K22: =VLOOKUP(A22,[1]Sheet4!A:B,2,FALSE) -> emergency_contact_name | L22: =VLOOKUP(K22,[3]Combined_Columns!$A:$B,2,FALSE) -> employee_contact | M22: =VLOOKUP(K22,[3]Combined_Columns!$A:$E,5,FALSE) -> varchar | N22: =ISERROR(SEARCH(M22, H22)) -> FALSE | O22: NO | P22: Emergency Contact Name | Q22: emergency_contact_name | R22: employee_contact | S22: =VLOOKUP(Q22,[2]Sheet2!$D:$E,2,FALSE) -> Y | T22: =VLOOKUP(Q22,[2]Sheet2!$D:$F,3,FALSE) -> 0 | U22: =VLOOKUP(Q22,[2]Sheet2!$D:$G,4,FALSE) -> 0
A23: Emergency Contact Phone | B23: ✔ | C23: ✔ | D23: — | E23: — | F23: IND | G23: both | H23: VARCHAR(20) | I23: IND only | J23: YES | K23: =VLOOKUP(A23,[1]Sheet4!A:B,2,FALSE) -> emergency_contact_phone | L23: =VLOOKUP(K23,[3]Combined_Columns!$A:$B,2,FALSE) -> employee_contact | M23: =VLOOKUP(K23,[3]Combined_Columns!$A:$E,5,FALSE) -> varchar | N23: =ISERROR(SEARCH(M23, H23)) -> FALSE | O23: NO | P23: Emergency Contact Phone | Q23: emergency_contact_phone | R23: employee_contact | S23: =VLOOKUP(Q23,[2]Sheet2!$D:$E,2,FALSE) -> Y | T23: =VLOOKUP(Q23,[2]Sheet2!$D:$F,3,FALSE) -> 0 | U23: =VLOOKUP(Q23,[2]Sheet2!$D:$G,4,FALSE) -> 0
... A37: End Contract | B37: ✔ | C37: ✔ | D37: ✔ | E37: ✔ | F37: BOTH | G37: both | H37: DATE | I37: — | J37: YES | K37: =VLOOKUP(A37,[1]Sheet4!A:B,2,FALSE) -> end_contract | L37: =VLOOKUP(K37,[3]Combined_Columns!$A:$B,2,FALSE) -> employee_onboard | M37: =VLOOKUP(K37,[3]Combined_Columns!$A:$E,5,FALSE) -> date | N37: =ISERROR(SEARCH(M37, H37)) -> FALSE | O37: NO | P37: End Contract | Q37: end_contract | R37: employee_onboard | S37: =VLOOKUP(Q37,[2]Sheet2!$D:$E,2,FALSE) -> Y | T37: =VLOOKUP(Q37,[2]Sheet2!$D:$F,3,FALSE) -> 0 | U37: =VLOOKUP(Q37,[2]Sheet2!$D:$G,4,FALSE) -> Y
A38: Years in Service | B38: ✔ | C38: ✔ | D38: ✔ | E38: ✔ | F38: BOTH | G38: both | H38: VARCHAR(50) | I38: As-is: “2Tahun11Bulan” | J38: NO | K38: years_in_service | L38: =VLOOKUP(K38,[3]Combined_Columns!$A:$B,2,FALSE) -> employee_onboard | M38: =VLOOKUP(K38,[3]Combined_Columns!$A:$E,5,FALSE) -> int | N38: =ISERROR(SEARCH(M38, H38)) -> TRUE | O38: NO | P38: Years in Service | Q38: years_in_service | R38: employee_onboard | S38: =VLOOKUP(Q38,[2]Sheet2!$D:$E,2,FALSE) -> Y | T38: =VLOOKUP(Q38,[2]Sheet2!$D:$F,3,FALSE) -> 0 | U38: =VLOOKUP(Q38,[2]Sheet2!$D:$G,4,FALSE) -> Y
A39: Branch ID | B39: ✔ | C39: ✔ | D39: — | E39: — | F39: IND | G39: both | H39: VARCHAR(20) | I39: IND | J39: YES | K39: =VLOOKUP(A39,[1]Sheet4!A:B,2,FALSE) -> 0 | M39: =VLOOKUP(K39,[3]Combined_Columns!$A:$E,5,FALSE) -> #N/A | O39: YES | P39: Branch ID | Q39: branch_id | R39: employee_core | S39: =VLOOKUP(Q39,[2]Sheet2!$D:$E,2,FALSE) -> #N/A | T39: =VLOOKUP(Q39,[2]Sheet2!$D:$F,3,FALSE) -> #N/A | U39: =VLOOKUP(Q39,[2]Sheet2!$D:$G,4,FALSE) -> #N/A
A40: Branch | B40: ✔ | C40: ✔ | D40: — | E40: — | F40: IND | G40: both | H40: VARCHAR(50) | I40: — | J40: YES | K40: =VLOOKUP(A40,[1]Sheet4!A:B,2,FALSE) -> 0 | M40: =VLOOKUP(K40,[3]Combined_Columns!$A:$E,5,FALSE) -> #N/A | O40: YES | P40: Branch | Q40: branch | R40: employee_core | S40: =VLOOKUP(Q40,[2]Sheet2!$D:$E,2,FALSE) -> #N/A | T40: =VLOOKUP(Q40,[2]Sheet2!$D:$F,3,FALSE) -> #N/A | U40: =VLOOKUP(Q40,[2]Sheet2!$D:$G,4,FALSE) -> #N/A
A41: Company Office | B41: — | C41: — | D41: ✔ | E41: ✔ | F41: EXP | G41: both | H41: VARCHAR(100) | I41: EXP only | J41: YES | K41: =VLOOKUP(A41,[1]Sheet4!A:B,2,FALSE) -> company_office | L41: =VLOOKUP(K41,[3]Combined_Columns!$A:$B,2,FALSE) -> employee_employment | M41: =VLOOKUP(K41,[3]Combined_Columns!$A:$E,5,FALSE) -> varchar | N41: =ISERROR(SEARCH(M41, H41)) -> FALSE | O41: NO | P41: Company Office | Q41: company_office | R41: employee_employment | S41: =VLOOKUP(Q41,[2]Sheet2!$D:$E,2,FALSE) -> Y | T41: =VLOOKUP(Q41,[2]Sheet2!$D:$F,3,FALSE) -> Y | U41: =VLOOKUP(Q41,[2]Sheet2!$D:$G,4,FALSE) -> 0
A42: Work Location | B42: — | C42: — | D42: ✔ | E42: ✔ | F42: EXP | G42: both | H42: VARCHAR(100) | I42: EXP only | J42: YES | K42: =VLOOKUP(A42,[1]Sheet4!A:B,2,FALSE) -> work_location | L42: =VLOOKUP(K42,[3]Combined_Columns!$A:$B,2,FALSE) -> employee_employment | M42: =VLOOKUP(K42,[3]Combined_Columns!$A:$E,5,FALSE) -> varchar | N42: =ISERROR(SEARCH(M42, H42)) -> FALSE | O42: NO | P42: Work Location | Q42: work_location | R42: employee_employment | S42: =VLOOKUP(Q42,[2]Sheet2!$D:$E,2,FALSE) -> Y | T42: =VLOOKUP(Q42,[2]Sheet2!$D:$F,3,FALSE) -> Y | U42: =VLOOKUP(Q42,[2]Sheet2!$D:$G,4,FALSE) -> 0
A43: Division | B43: ✔ | C43: ✔ | D43: ✔ | E43: ✔ | F43: BOTH | G43: both | H43: VARCHAR(100) | I43: — | J43: YES | K43: =VLOOKUP(A43,[1]Sheet4!A:B,2,FALSE) -> division | L43: =VLOOKUP(K43,[3]Combined_Columns!$A:$B,2,FALSE) -> employee_employment | M43: =VLOOKUP(K43,[3]Combined_Columns!$A:$E,5,FALSE) -> varchar | N43: =ISERROR(SEARCH(M43, H43)) -> FALSE | O43: NO | P43: Division | Q43: division | R43: employee_employment | S43: =VLOOKUP(Q43,[2]Sheet2!$D:$E,2,FALSE) -> Y | T43: =VLOOKUP(Q43,[2]Sheet2!$D:$F,3,FALSE) -> Y | U43: =VLOOKUP(Q43,[2]Sheet2!$D:$G,4,FALSE) -> 0
A44: Department | B44: ✔ | C44: ✔ | D44: ✔ | E44: ✔ | F44: BOTH | G44: both | H44: VARCHAR(100) | I44: — | J44: YES | K44: =VLOOKUP(A44,[1]Sheet4!A:B,2,FALSE) -> department | L44: =VLOOKUP(K44,[3]Combined_Columns!$A:$B,2,FALSE) -> employee_employment | M44: =VLOOKUP(K44,[3]Combined_Columns!$A:$E,5,FALSE) -> varchar | N44: =ISERROR(SEARCH(M44, H44)) -> FALSE | O44: NO | P44: Department | Q44: department | R44: employee_employment | S44: =VLOOKUP(Q44,[2]Sheet2!$D:$E,2,FALSE) -> Public | T44: =VLOOKUP(Q44,[2]Sheet2!$D:$F,3,FALSE) -> Public | U44: =VLOOKUP(Q44,[2]Sheet2!$D:$G,4,FALSE) -> Public
A45: Section | B45: ✔ | C45: ✔ | D45: ✔ | E45: ✔ | F45: BOTH | G45: both | H45: VARCHAR(100) | I45: — | J45: YES | K45: =VLOOKUP(A45,[1]Sheet4!A:B,2,FALSE) -> section | L45: =VLOOKUP(K45,[3]Combined_Columns!$A:$B,2,FALSE) -> employee_employment | M45: =VLOOKUP(K45,[3]Combined_Columns!$A:$E,5,FALSE) -> varchar | N45: =ISERROR(SEARCH(M45, H45)) -> FALSE | O45: NO | P45: Section | Q45: section | R45: employee_employment | S45: =VLOOKUP(Q45,[2]Sheet2!$D:$E,2,FALSE) -> Public | T45: =VLOOKUP(Q45,[2]Sheet2!$D:$F,3,FALSE) -> Public | U45: =VLOOKUP(Q45,[2]Sheet2!$D:$G,4,FALSE) -> Public
A46: Direct Report | B46: ✔ | C46: ✔ | D46: ✔ | E46: ✔ | F46: BOTH | G46: both | H46: VARCHAR(100) | I46: Supervisor | J46: YES | K46: =VLOOKUP(A46,[1]Sheet4!A:B,2,FALSE) -> direct_report | L46: =VLOOKUP(K46,[3]Combined_Columns!$A:$B,2,FALSE) -> employee_employment | M46: =VLOOKUP(K46,[3]Combined_Columns!$A:$E,5,FALSE) -> varchar | N46: =ISERROR(SEARCH(M46, H46)) -> FALSE | O46: NO | P46: Direct Report | Q46: direct_report | R46: employee_employment | S46: =VLOOKUP(Q46,[2]Sheet2!$D:$E,2,FALSE) -> Y | T46: =VLOOKUP(Q46,[2]Sheet2!$D:$F,3,FALSE) -> Y | U46: =VLOOKUP(Q46,[2]Sheet2!$D:$G,4,FALSE) -> 0
A47: Job Title | B47: ✔ | C47: ✔ | D47: ✔ | E47: ✔ | F47: BOTH | G47: both | H47: VARCHAR(100) | I47: — | J47: YES | K47: =VLOOKUP(A47,[1]Sheet4!A:B,2,FALSE) -> job_title | L47: =VLOOKUP(K47,[3]Combined_Columns!$A:$B,2,FALSE) -> employee_employment | M47: =VLOOKUP(K47,[3]Combined_Columns!$A:$E,5,FALSE) -> varchar | N47: =ISERROR(SEARCH(M47, H47)) -> FALSE | O47: NO | P47: Job Title | Q47: job_title | R47: employee_employment | S47: =VLOOKUP(Q47,[2]Sheet2!$D:$E,2,FALSE) -> Public | T47: =VLOOKUP(Q47,[2]Sheet2!$D:$F,3,FALSE) -> Public | U47: =VLOOKUP(Q47,[2]Sheet2!$D:$G,4,FALSE) -> Public
A48: Grade | B48: ✔ | C48: ✔ | D48: ✔ | E48: ✔ | F48: BOTH | G48: both | H48: VARCHAR(10) | I48: — | J48: YES | K48: =VLOOKUP(A48,[1]Sheet4!A:B,2,FALSE) -> grade | L48: =VLOOKUP(K48,[3]Combined_Columns!$A:$B,2,FALSE) -> employee_employment | M48: =VLOOKUP(K48,[3]Combined_Columns!$A:$E,5,FALSE) -> varchar | N48: =ISERROR(SEARCH(M48, H48)) -> FALSE | O48: NO | P48: Grade | Q48: grade | R48: employee_employment | S48: =VLOOKUP(Q48,[2]Sheet2!$D:$E,2,FALSE) -> Confidential | T48: =VLOOKUP(Q48,[2]Sheet2!$D:$F,3,FALSE) -> Confidential | U48: =VLOOKUP(Q48,[2]Sheet2!$D:$G,4,FALSE) -> Confidential
A49: Position Grade | B49: ✔ | C49: ✔ | D49: ✔ | E49: ✔ | F49: BOTH | G49: both | H49: VARCHAR(50) | I49: Staff/NonStaff | J49: YES | K49: =VLOOKUP(A49,[1]Sheet4!A:B,2,FALSE) -> position_grade | L49: =VLOOKUP(K49,[3]Combined_Columns!$A:$B,2,FALSE) -> employee_employment | M49: =VLOOKUP(K49,[3]Combined_Columns!$A:$E,5,FALSE) -> varchar | N49: =ISERROR(SEARCH(M49, H49)) -> FALSE | O49: NO | P49: Position Grade | Q49: position_grade | R49: employee_employment | S49: =VLOOKUP(Q49,[2]Sheet2!$D:$E,2,FALSE) -> Public | T49: =VLOOKUP(Q49,[2]Sheet2!$D:$F,3,FALSE) -> Public | U49: =VLOOKUP(Q49,[2]Sheet2!$D:$G,4,FALSE) -> Public
A50: Group Job Title | B50: ✔ | C50: ✔ | D50: ✔ | E50: ✔ | F50: BOTH | G50: both | H50: VARCHAR(100) | I50: — | J50: YES | K50: =VLOOKUP(A50,[1]Sheet4!A:B,2,FALSE) -> group_job_title | L50: =VLOOKUP(K50,[3]Combined_Columns!$A:$B,2,FALSE) -> employee_employment | M50: =VLOOKUP(K50,[3]Combined_Columns!$A:$E,5,FALSE) -> varchar | N50: =ISERROR(SEARCH(M50, H50)) -> FALSE | O50: NO | P50: Group Job Title | Q50: group_job_title | R50: employee_employment | S50: =VLOOKUP(Q50,[2]Sheet2!$D:$E,2,FALSE) -> Y | T50: =VLOOKUP(Q50,[2]Sheet2!$D:$F,3,FALSE) -> Y | U50: =VLOOKUP(Q50,[2]Sheet2!$D:$G,4,FALSE) -> 0
A51: Bank Name | B51: ✔ | C51: ✔ | D51: — | E51: — | F51: IND | G51: both | H51: VARCHAR(100) | I51: IND | J51: YES | K51: =VLOOKUP(A51,[1]Sheet4!A:B,2,FALSE) -> bank_name | L51: =VLOOKUP(K51,[3]Combined_Columns!$A:$B,2,FALSE) -> employee_bank | M51: =VLOOKUP(K51,[3]Combined_Columns!$A:$E,5,FALSE) -> varchar | N51: =ISERROR(SEARCH(M51, H51)) -> FALSE | O51: NO | P51: Bank Name | Q51: bank_name | R51: employee_bank | S51: =VLOOKUP(Q51,[2]Sheet2!$D:$E,2,FALSE) -> 0 | T51: =VLOOKUP(Q51,[2]Sheet2!$D:$F,3,FALSE) -> Y | U51: =VLOOKUP(Q51,[2]Sheet2!$D:$G,4,FALSE) -> 0
A52: Account Name | B52: ✔ | C52: ✔ | D52: — | E52: — | F52: IND | G52: both | H52: VARCHAR(100) | I52: IND | J52: YES | K52: =VLOOKUP(A52,[1]Sheet4!A:B,2,FALSE) -> account_name | L52: =VLOOKUP(K52,[3]Combined_Columns!$A:$B,2,FALSE) -> employee_bank | M52: =VLOOKUP(K52,[3]Combined_Columns!$A:$E,5,FALSE) -> varchar | N52: =ISERROR(SEARCH(M52, H52)) -> FALSE | O52: NO | P52: Account Name | Q52: account_name | R52: employee_bank | S52: =VLOOKUP(Q52,[2]Sheet2!$D:$E,2,FALSE) -> 0 | T52: =VLOOKUP(Q52,[2]Sheet2!$D:$F,3,FALSE) -> Y | U52: =VLOOKUP(Q52,[2]Sheet2!$D:$G,4,FALSE) -> 0
... A61: Travel Out | B61: ✔ | C61: — | D61: ✔ | E61: — | F61: BOTH | G61: active | H61: DATE | I61: — | J61: YES | K61: =VLOOKUP(A61,[1]Sheet4!A:B,2,FALSE) -> travel_out | L61: =VLOOKUP(K61,[3]Combined_Columns!$A:$B,2,FALSE) -> employee_travel | M61: =VLOOKUP(K61,[3]Combined_Columns!$A:$E,5,FALSE) -> date | N61: =ISERROR(SEARCH(M61, H61)) -> FALSE | O61: NO | P61: Travel Out | Q61: travel_out | R61: employee_travel | S61: =VLOOKUP(Q61,[2]Sheet2!$D:$E,2,FALSE) -> Confidential | T61: =VLOOKUP(Q61,[2]Sheet2!$D:$F,3,FALSE) -> Confidential | U61: =VLOOKUP(Q61,[2]Sheet2!$D:$G,4,FALSE) -> Confidential
...
